Workbook

Sheet Sheet1
A1: Category ID | B1: Field ID | C1: Description | D1: Code | E1: Diseases | F1: DataType | G1: Types | H1: Type2
A2: 2401 | B2: 130000 | C2: Date A00 first reported (cholera) | D2: A00 | E2: cholera | F2: Date | G2: Bacterial infections | H2: =VLOOKUP(A2,Sheet2!A:B,2,FALSE) -> Certain infectious and parasitic diseases
A3: 2401 | B3: 130001 | C3: Source of report of A00 (cholera) | D3: A00 | E3: cholera | F3: Source | G3: Bacterial infections | H3: =VLOOKUP(A3,Sheet2!A:B,2,FALSE) -> Certain infectious and parasitic diseases
A4: 2401 | B4: 130002 | C4: Date A01 first reported (typhoid and paratyphoid fevers) | D4: A01 | E4: typhoid and paratyphoid fevers | F4: Date | G4: Bacterial infections | H4: =VLOOKUP(A4,Sheet2!A:B,2,FALSE) -> Certain infectious and parasitic diseases
A5: 2401 | B5: 130003 | C5: Source of report of A01 (typhoid and paratyphoid fevers) | D5: A01 | E5: typhoid and paratyphoid fevers | F5: Source | G5: Bacterial infections | H5: =VLOOKUP(A5,Sheet2!A:B,2,FALSE) -> Certain infectious and parasitic diseases
A6: 2401 | B6: 130004 | C6: Date A02 first reported (other salmonella infections) | D6: A02 | E6: other salmonella infections | F6: Date | G6: Bacterial infections | H6: =VLOOKUP(A6,Sheet2!A:B,2,FALSE) -> Certain infectious and parasitic diseases
A7: 2401 | B7: 130005 | C7: Source of report of A02 (other salmonella infections) | D7: A02 | E7: other salmonella infections | F7: Source | G7: Bacterial infections | H7: =VLOOKUP(A7,Sheet2!A:B,2,FALSE) -> Certain infectious and parasitic diseases
A8: 2401 | B8: 130006 | C8: Date A03 first reported (shigellosis) | D8: A03 | E8: shigellosis | F8: Date | G8: Bacterial infections | H8: =VLOOKUP(A8,Sheet2!A:B,2,FALSE) -> Certain infectious and parasitic diseases
A9: 2401 | B9: 130007 | C9: Source of report of A03 (shigellosis) | D9: A03 | E9: shigellosis | F9: Source | G9: Bacterial infections | H9: =VLOOKUP(A9,Sheet2!A:B,2,FALSE) -> Certain infectious and parasitic diseases
A10: 2401 | B10: 130008 | C10: Date A04 first reported (other bacterial intestinal infections) | D10: A04 | E10: other bacterial intestinal infections | F10: Date | G10: Bacterial infections | H10: =VLOOKUP(A10,Sheet2!A:B,2,FALSE) -> Certain infectious and parasitic diseases
A11: 2401 | B11: 130009 | C11: Source of report of A04 (other bacterial intestinal infections) | D11: A04 | E11: other bacterial intestinal infections | F11: Source | G11: Bacterial infections | H11: =VLOOKUP(A11,Sheet2!A:B,2,FALSE) -> Certain infectious and parasitic diseases
A12: 2401 | B12: 130010 | C12: Date A05 first reported (other bacterial foodborne intoxications) | D12: A05 | E12: other bacterial foodborne intoxications | F12: Date | G12: Bacterial infections | H12: =VLOOKUP(A12,Sheet2!A:B,2,FALSE) -> Certain infectious and parasitic diseases
A13: 2401 | B13: 130011 | C13: Source of report of A05 (other bacterial foodborne intoxications) | D13: A05 | E13: other bacterial foodborne intoxications | F13: Source | G13: Bacterial infections | H13: =VLOOKUP(A13,Sheet2!A:B,2,FALSE) -> Certain infectious and parasitic diseases
... A227: 2401 | B227: 130225 | C227: Source of report of B34 (viral infection of unspecified site) | D227: B34 | E227: viral infection of unspecified site | F227: Source | G227: Viral infections | H227: =VLOOKUP(A227,Sheet2!A:B,2,FALSE) -> Certain infectious and parasitic diseases
A228: 2401 | B228: 130226 | C228: Date B35 first reported (dermatophytosis) | D228: B35 | E228: dermatophytosis | F228: Date | H228: =VLOOKUP(A228,Sheet2!A:B,2,FALSE) -> Certain infectious and parasitic diseases
A229: 2401 | B229: 130227 | C229: Source of report of B35 (dermatophytosis) | D229: B35 | E229: dermatophytosis | F229: Source | H229: =VLOOKUP(A229,Sheet2!A:B,2,FALSE) -> Certain infectious and parasitic diseases
A230: 2401 | B230: 130228 | C230: Date B36 first reported (other superficial mycoses) | D230: B36 | E230: other superficial mycoses | F230: Date | H230: =VLOOKUP(A230,Sheet2!A:B,2,FALSE) -> Certain infectious and parasitic diseases
A231: 2401 | B231: 130229 | C231: Source of report of B36 (other superficial mycoses) | D231: B36 | E231: other superficial mycoses | F231: Source | H231: =VLOOKUP(A231,Sheet2!A:B,2,FALSE) -> Certain infectious and parasitic diseases
A232: 2401 | B232: 130230 | C232: Date B37 first reported (candidiasis) | D232: B37 | E232: candidiasis | F232: Date | H232: =VLOOKUP(A232,Sheet2!A:B,2,FALSE) -> Certain infectious and parasitic diseases
A233: 2401 | B233: 130231 | C233: Source of report of B37 (candidiasis) | D233: B37 | E233: candidiasis | F233: Source | H233: =VLOOKUP(A233,Sheet2!A:B,2,FALSE) -> Certain infectious and parasitic diseases
A234: 2401 | B234: 130232 | C234: Date B38 first reported (coccidioidomycosis) | D234: B38 | E234: coccidioidomycosis | F234: Date | H234: =VLOOKUP(A234,Sheet2!A:B,2,FALSE) -> Certain infectious and parasitic diseases
A235: 2401 | B235: 130233 | C235: Source of report of B38 (coccidioidomycosis) | D235: B38 | E235: coccidioidomycosis | F235: Source | H235: =VLOOKUP(A235,Sheet2!A:B,2,FALSE) -> Certain infectious and parasitic diseases
A236: 2401 | B236: 130234 | C236: Date B39 first reported (histoplasmosis) | D236: B39 | E236: histoplasmosis | F236: Date | H236: =VLOOKUP(A236,Sheet2!A:B,2,FALSE) -> Certain infectious and parasitic diseases
A237: 2401 | B237: 130235 | C237: Source of report of B39 (histoplasmosis) | D237: B39 | E237: histoplasmosis | F237: Source | H237: =VLOOKUP(A237,Sheet2!A:B,2,FALSE) -> Certain infectious and parasitic diseases
A238: 2401 | B238: 130236 | C238: Date B40 first reported (blastomycosis) | D238: B40 | E238: blastomycosis | F238: Date | H238: =VLOOKUP(A238,Sheet2!A:B,2,FALSE) -> Certain infectious and parasitic diseases
A239: 2401 | B239: 130237 | C239: Source of report of B40 (blastomycosis) | D239: B40 | E239: blastomycosis | F239: Source | H239: =VLOOKUP(A239,Sheet2!A:B,2,FALSE) -> Certain infectious and parasitic diseases
... A347: 2401 | B347: 130345 | C347: Source of report of B99 (other and unspecified infectious diseases) | D347: B99 | E347: other and unspecified infectious diseases | F347: Source | H347: =VLOOKUP(A347,Sheet2!A:B,2,FALSE) -> Certain infectious and parasitic diseases
A348: 2403 | B348: 130622 | C348: Date D50 first reported (iron deficiency anaemia) | D348: D50 | E348: iron deficiency anaemia | F348: Date | G348: Anemia | H348: =VLOOKUP(A348,Sheet2!A:B,2,FALSE) -> Blood, blood-forming organs and certain immune disorders
A349: 2403 | B349: 130623 | C349: Source of report of D50 (iron deficiency anaemia) | D349: D50 | E349: iron deficiency anaemia | F349: Source | G349: Anemia | H349: =VLOOKUP(A349,Sheet2!A:B,2,FALSE) -> Blood, blood-forming organs and certain immune disorders
A350: 2403 | B350: 130624 | C350: Date D51 first reported (vitamin b12 deficiency anaemia) | D350: D51 | E350: vitamin b12 deficiency anaemia | F350: Date | G350: Anemia | H350: =VLOOKUP(A350,Sheet2!A:B,2,FALSE) -> Blood, blood-forming organs and certain immune disorders
A351: 2403 | B351: 130625 | C351: Source of report of D51 (vitamin b12 deficiency anaemia) | D351: D51 | E351: vitamin b12 deficiency anaemia | F351: Source | G351: Anemia | H351: =VLOOKUP(A351,Sheet2!A:B,2,FALSE) -> Blood, blood-forming organs and certain immune disorders
A352: 2403 | B352: 130626 | C352: Date D52 first reported (folate deficiency anaemia) | D352: D52 | E352: folate deficiency anaemia | F352: Date | G352: Anemia | H352: =VLOOKUP(A352,Sheet2!A:B,2,FALSE) -> Blood, blood-forming organs and certain immune disorders
A353: 2403 | B353: 130627 | C353: Source of report of D52 (folate deficiency anaemia) | D353: D52 | E353: folate deficiency anaemia | F353: Source | G353: Anemia | H353: =VLOOKUP(A353,Sheet2!A:B,2,FALSE) -> Blood, blood-forming organs and certain immune disorders
A354: 2403 | B354: 130628 | C354: Date D53 first reported (other nutritional anaemias) | D354: D53 | E354: other nutritional anaemias | F354: Date | G354: Anemia | H354: =VLOOKUP(A354,Sheet2!A:B,2,FALSE) -> Blood, blood-forming organs and certain immune disorders
A355: 2403 | B355: 130629 | C355: Source of report of D53 (other nutritional anaemias) | D355: D53 | E355: other nutritional anaemias | F355: Source | G355: Anemia | H355: =VLOOKUP(A355,Sheet2!A:B,2,FALSE) -> Blood, blood-forming organs and certain immune disorders
A356: 2403 | B356: 130630 | C356: Date D55 first reported (anaemia due to enzyme disorders) | D356: D55 | E356: anaemia due to enzyme disorders | F356: Date | G356: Anemia | H356: =VLOOKUP(A356,Sheet2!A:B,2,FALSE) -> Blood, blood-forming organs and certain immune disorders
A357: 2403 | B357: 130631 | C357: Source of report of D55 (anaemia due to enzyme disorders) | D357: D55 | E357: anaemia due to enzyme disorders | F357: Source | G357: Anemia | H357: =VLOOKUP(A357,Sheet2!A:B,2,FALSE) -> Blood, blood-forming organs and certain immune disorders
A358: 2403 | B358: 130632 | C358: Date D56 first reported (thalassaemia) | D358: D56 | E358: thalassaemia | F358: Date | G358: Anemia | H358: =VLOOKUP(A358,Sheet2!A:B,2,FALSE) -> Blood, blood-forming organs and certain immune disorders
A359: 2403 | B359: 130633 | C359: Source of report of D56 (thalassaemia) | D359: D56 | E359: thalassaemia | F359: Source | G359: Anemia | H359: =VLOOKUP(A359,Sheet2!A:B,2,FALSE) -> Blood, blood-forming organs and certain immune disorders
... A375: 2403 | B375: 130649 | C375: Source of report of D64 (other anaemias) | D375: D64 | E375: other anaemias | F375: Source | G375: Anemia | H375: =VLOOKUP(A375,Sheet2!A:B,2,FALSE) -> Blood, blood-forming organs and certain immune disorders
...

Sheet Sheet4
A1: Coding | B1: Meaning
A2: 20 | B2: Death register only
A3: 21 | B3: Death register and other source(s)
A4: 30 | B4: Primary care only
A5: 31 | B5: Primary care and other source(s)
A6: 40 | B6: Hospital admissions data only
A7: 41 | B7: Hospital admissions data and other source(s)
A8: 50 | B8: Self-report only
A9: 51 | B9: Self-report and other source(s)

Sheet Sheet3
A1: Field ID | B1: Description
A2: 40021 | B2: Cancer record origin
A3: 40019 | B3: Cancer record format
A4: 40009 | B4: Reported occurrences of cancer
A5: 40005 | B5: Date of cancer diagnosis
A6: 40008 | B6: Age at cancer diagnosis
A7: 40006 | B7: Type of cancer: ICD10
A8: 40013 | B8: Type of cancer: ICD9
A9: 40011 | B9: Histology of cancer tumour
A10: 40012 | B10: Behaviour of cancer tumour

Sheet Sheet2
A1: Category ID | B1: Description | C1: Items
A2: 2401 | B2: Certain infectious and parasitic diseases | C2: 346
A3: 2403 | B3: Blood, blood-forming organs and certain immune disorders | C3: 68
A4: 2404 | B4: Endocrine, nutritional and metabolic diseases | C4: 146
A5: 2405 | B5: Mental and behavioural disorders | C5: 156
A6: 2406 | B6: Nervous system disorders | C6: 136
A7: 2407 | B7: Eye and adnexa disorders | C7: 94
A8: 2408 | B8: Ear and mastoid process disorders | C8: 48
A9: 2409 | B9: Circulatory system disorders | C9: 154
A10: 2410 | B10: Respiratory system disorders | C10: 128
A11: 2411 | B11: Digestive system disorders | C11: 144
A12: 2412 | B12: Skin and subcutaneous tissue disorders | C12: 144
A13: 2413 | B13: Musculoskeletal system and connective tissue disorders | C13: 158
... A17: 2417 | B17: Congenital disruptions and chromosomal abnormalities | C17: 174
